<?xml version="1.0"?>
<robot xmlns:xacro="http://ros.org/wiki/xacro">
    <xacro:macro name="gripper_hand" params="side order length width height pos_x pos_y pos_z mass">
        <link name="${side}_${order}_gripper_hand_link">
        <visual>
            <origin xyz="0 0 0" rpy="0 0 0"/>
            <geometry>
                <box size="${length} ${width} ${height}"/>
                <!-- <mesh filename="file://$(find abu_description)/urdf/model/gripper_hand.dae" scale="1 1 1"/> -->
            </geometry>
            <material name="gray">
                <color rgba="0.123 0.114 0.119 0.8"/>
            </material>
        </visual>
        <collision>
            <origin xyz="0 0 0" rpy="0 0 0"/>
            <geometry>
                <box size="${length} ${width} ${height}"/>
                <!-- <mesh filename="file://$(find abu_description)/urdf/model/gripper_hand.dae" scale="1 1 1"/> -->
            </geometry>
        </collision>

        <inertial>
            <origin xyz="0 0 0" rpy="0 0 0"/>
            <mass value="${mass}"/>
            <inertia ixx="${(1/12) * mass * ((width  * width)  + (height * height))}" ixy="0.0" ixz="0.0"
                    iyy="${(1/12) * mass * ((length * length) + (height * height))}" iyz="0.0"
                    izz="${(1/12) * mass * ((length * length) + (width  * width))}"/>
        </inertial>
        </link>

        <gazebo reference="${side}_${order}_gripper_hand_link">  
        <visual>  
            <material>
            <ambient>0.123 0.114 0.119 0.8</ambient>  
            <diffuse>0.123 0.114 0.119 0.8</diffuse>  
            <specular>0.123 0.114 0.119 0.8</specular>  
            <emissive>0.0 0.0 0.0 0.0</emissive>  
            </material>
        </visual>  
        </gazebo>
        <xacro:if value="${order == 1}">
            <joint name="${side}_${order}_gripper_hand_joint" type="prismatic">
                <axis xyz="1 0 0" />
                <parent link="${side}_gripper_wrist_link"/>
                <child link="${side}_${order}_gripper_hand_link"/>
                <origin xyz="${pos_x} ${pos_y} ${pos_z}" rpy="0 0 0"/>
                <limit lower="0" upper="0.015" effort="-1" velocity="-1"/>
            </joint>
        </xacro:if>
        <xacro:if value="${order == 2}">
            <joint name="${side}_${order}_gripper_hand_joint" type="prismatic">
                <axis xyz="1 0 0" />
                <parent link="${side}_gripper_wrist_link"/>
                <child link="${side}_${order}_gripper_hand_link"/>
                <origin xyz="${pos_x} ${pos_y} ${pos_z}" rpy="0 0 ${pi}"/>
                <limit lower="0" upper="0.015" effort="-1" velocity="-1"/>
                <!-- <mimic joint="${side}_1_gripper_hand_joint" /> -->
            </joint>
        </xacro:if>
    </xacro:macro>
</robot>